[2023-11-07T00:04:45.114+0000] {taskinstance.py:1159} INFO - Dependencies all met for dep_context=non-requeueable deps ti=<TaskInstance: yahoo_finance_elt_pipeline_v3.load_to_s3_task manual__2023-11-06T23:58:24.604883+00:00 [queued]>
[2023-11-07T00:04:45.146+0000] {taskinstance.py:1159} INFO - Dependencies all met for dep_context=requeueable deps ti=<TaskInstance: yahoo_finance_elt_pipeline_v3.load_to_s3_task manual__2023-11-06T23:58:24.604883+00:00 [queued]>
[2023-11-07T00:04:45.159+0000] {taskinstance.py:1361} INFO - Starting attempt 2 of 6
[2023-11-07T00:04:45.228+0000] {taskinstance.py:1382} INFO - Executing <Task(PythonOperator): load_to_s3_task> on 2023-11-06 23:58:24.604883+00:00
[2023-11-07T00:04:45.255+0000] {standard_task_runner.py:57} INFO - Started process 642 to run task
[2023-11-07T00:04:45.284+0000] {standard_task_runner.py:84} INFO - Running: ['***', 'tasks', 'run', 'yahoo_finance_elt_pipeline_v3', 'load_to_s3_task', 'manual__2023-11-06T23:58:24.604883+00:00', '--job-id', '45', '--raw', '--subdir', 'DAGS_FOLDER/yahoo_elt_pipeline.py', '--cfg-path', '/tmp/tmpmcme786c']
[2023-11-07T00:04:45.293+0000] {standard_task_runner.py:85} INFO - Job 45: Subtask load_to_s3_task
[2023-11-07T00:04:45.560+0000] {task_command.py:416} INFO - Running <TaskInstance: yahoo_finance_elt_pipeline_v3.load_to_s3_task manual__2023-11-06T23:58:24.604883+00:00 [running]> on host a5d58a06784e
[2023-11-07T00:04:45.872+0000] {taskinstance.py:1662} INFO - Exporting env vars: AIRFLOW_CTX_DAG_OWNER='mbahraoui' AIRFLOW_CTX_DAG_ID='yahoo_finance_elt_pipeline_v3' AIRFLOW_CTX_TASK_ID='load_to_s3_task' AIRFLOW_CTX_EXECUTION_DATE='2023-11-06T23:58:24.604883+00:00' AIRFLOW_CTX_TRY_NUMBER='2' AIRFLOW_CTX_DAG_RUN_ID='manual__2023-11-06T23:58:24.604883+00:00'
[2023-11-07T00:04:48.279+0000] {taskinstance.py:1937} ERROR - Task failed with exception
Traceback (most recent call last):
  File "/home/airflow/.local/lib/python3.8/site-packages/airflow/operators/python.py", line 192, in execute
    return_value = self.execute_callable()
  File "/home/airflow/.local/lib/python3.8/site-packages/airflow/operators/python.py", line 209, in execute_callable
    return self.python_callable(*self.op_args, **self.op_kwargs)
  File "/opt/airflow/dags/yahoo_elt_pipeline.py", line 67, in load_to_s3
    company_object = s3.Object(s3_bucket_name, 'company_info.csv')
  File "/home/airflow/.local/lib/python3.8/site-packages/botocore/client.py", line 888, in __getattr__
    raise AttributeError(
AttributeError: 'S3' object has no attribute 'Object'
[2023-11-07T00:04:48.304+0000] {taskinstance.py:1400} INFO - Marking task as UP_FOR_RETRY. dag_id=yahoo_finance_elt_pipeline_v3, task_id=load_to_s3_task, execution_date=20231106T235824, start_date=20231107T000445, end_date=20231107T000448
[2023-11-07T00:04:48.348+0000] {standard_task_runner.py:104} ERROR - Failed to execute job 45 for task load_to_s3_task ('S3' object has no attribute 'Object'; 642)
[2023-11-07T00:04:48.405+0000] {local_task_job_runner.py:228} INFO - Task exited with return code 1
[2023-11-07T00:04:48.480+0000] {taskinstance.py:2778} INFO - 0 downstream tasks scheduled from follow-on schedule check
