[2023-11-07T00:29:01.064+0000] {taskinstance.py:1159} INFO - Dependencies all met for dep_context=non-requeueable deps ti=<TaskInstance: yahoo_finance_elt_pipeline_v6.load_to_s3_task manual__2023-11-07T00:26:53.185318+00:00 [queued]>
[2023-11-07T00:29:01.112+0000] {taskinstance.py:1159} INFO - Dependencies all met for dep_context=requeueable deps ti=<TaskInstance: yahoo_finance_elt_pipeline_v6.load_to_s3_task manual__2023-11-07T00:26:53.185318+00:00 [queued]>
[2023-11-07T00:29:01.121+0000] {taskinstance.py:1361} INFO - Starting attempt 1 of 6
[2023-11-07T00:29:01.250+0000] {taskinstance.py:1382} INFO - Executing <Task(PythonOperator): load_to_s3_task> on 2023-11-07 00:26:53.185318+00:00
[2023-11-07T00:29:01.363+0000] {standard_task_runner.py:57} INFO - Started process 1312 to run task
[2023-11-07T00:29:01.631+0000] {standard_task_runner.py:84} INFO - Running: ['***', 'tasks', 'run', 'yahoo_finance_elt_pipeline_v6', 'load_to_s3_task', 'manual__2023-11-07T00:26:53.185318+00:00', '--job-id', '53', '--raw', '--subdir', 'DAGS_FOLDER/yahoo_elt_pipeline.py', '--cfg-path', '/tmp/tmpdavio6ll']
[2023-11-07T00:29:01.671+0000] {standard_task_runner.py:85} INFO - Job 53: Subtask load_to_s3_task
[2023-11-07T00:29:02.434+0000] {task_command.py:416} INFO - Running <TaskInstance: yahoo_finance_elt_pipeline_v6.load_to_s3_task manual__2023-11-07T00:26:53.185318+00:00 [running]> on host a5d58a06784e
[2023-11-07T00:29:03.262+0000] {taskinstance.py:1662} INFO - Exporting env vars: AIRFLOW_CTX_DAG_OWNER='mbahraoui' AIRFLOW_CTX_DAG_ID='yahoo_finance_elt_pipeline_v6' AIRFLOW_CTX_TASK_ID='load_to_s3_task' AIRFLOW_CTX_EXECUTION_DATE='2023-11-07T00:26:53.185318+00:00' AIRFLOW_CTX_TRY_NUMBER='1' AIRFLOW_CTX_DAG_RUN_ID='manual__2023-11-07T00:26:53.185318+00:00'
[2023-11-07T00:29:08.527+0000] {taskinstance.py:1937} ERROR - Task failed with exception
Traceback (most recent call last):
  File "/home/airflow/.local/lib/python3.8/site-packages/airflow/operators/python.py", line 192, in execute
    return_value = self.execute_callable()
  File "/home/airflow/.local/lib/python3.8/site-packages/airflow/operators/python.py", line 209, in execute_callable
    return self.python_callable(*self.op_args, **self.op_kwargs)
  File "/opt/airflow/dags/yahoo_elt_pipeline.py", line 67, in load_to_s3
    if not (file_exists):
NameError: name 'file_exists' is not defined
[2023-11-07T00:29:08.619+0000] {taskinstance.py:1400} INFO - Marking task as UP_FOR_RETRY. dag_id=yahoo_finance_elt_pipeline_v6, task_id=load_to_s3_task, execution_date=20231107T002653, start_date=20231107T002901, end_date=20231107T002908
[2023-11-07T00:29:08.715+0000] {standard_task_runner.py:104} ERROR - Failed to execute job 53 for task load_to_s3_task (name 'file_exists' is not defined; 1312)
[2023-11-07T00:29:08.863+0000] {local_task_job_runner.py:228} INFO - Task exited with return code 1
[2023-11-07T00:29:09.069+0000] {taskinstance.py:2778} INFO - 0 downstream tasks scheduled from follow-on schedule check
