[2023-11-06T17:20:49.432+0000] {taskinstance.py:1159} INFO - Dependencies all met for dep_context=non-requeueable deps ti=<TaskInstance: yahoo_finance_elt_pipeline_v2.extract_data_task manual__2023-11-06T17:14:19.203558+00:00 [queued]>
[2023-11-06T17:20:49.528+0000] {taskinstance.py:1159} INFO - Dependencies all met for dep_context=requeueable deps ti=<TaskInstance: yahoo_finance_elt_pipeline_v2.extract_data_task manual__2023-11-06T17:14:19.203558+00:00 [queued]>
[2023-11-06T17:20:49.535+0000] {taskinstance.py:1361} INFO - Starting attempt 2 of 6
[2023-11-06T17:20:49.854+0000] {taskinstance.py:1382} INFO - Executing <Task(PythonOperator): extract_data_task> on 2023-11-06 17:14:19.203558+00:00
[2023-11-06T17:20:50.056+0000] {standard_task_runner.py:57} INFO - Started process 1316 to run task
[2023-11-06T17:20:50.399+0000] {standard_task_runner.py:84} INFO - Running: ['***', 'tasks', 'run', 'yahoo_finance_elt_pipeline_v2', 'extract_data_task', 'manual__2023-11-06T17:14:19.203558+00:00', '--job-id', '8', '--raw', '--subdir', 'DAGS_FOLDER/yahoo_elt_pipeline.py', '--cfg-path', '/tmp/tmps0rxte40']
[2023-11-06T17:20:50.465+0000] {standard_task_runner.py:85} INFO - Job 8: Subtask extract_data_task
[2023-11-06T17:20:51.583+0000] {task_command.py:416} INFO - Running <TaskInstance: yahoo_finance_elt_pipeline_v2.extract_data_task manual__2023-11-06T17:14:19.203558+00:00 [running]> on host a5d58a06784e
[2023-11-06T17:20:52.052+0000] {taskinstance.py:1662} INFO - Exporting env vars: AIRFLOW_CTX_DAG_OWNER='mbahraoui' AIRFLOW_CTX_DAG_ID='yahoo_finance_elt_pipeline_v2' AIRFLOW_CTX_TASK_ID='extract_data_task' AIRFLOW_CTX_EXECUTION_DATE='2023-11-06T17:14:19.203558+00:00' AIRFLOW_CTX_TRY_NUMBER='2' AIRFLOW_CTX_DAG_RUN_ID='manual__2023-11-06T17:14:19.203558+00:00'
[2023-11-06T17:20:55.350+0000] {logging_mixin.py:151} INFO - [*********************100%%**********************]  1 of 1 completed
[2023-11-06T17:21:00.943+0000] {logging_mixin.py:151} INFO - [*********************100%%**********************]  1 of 1 completed
[2023-11-06T17:21:08.985+0000] {logging_mixin.py:151} INFO - [*********************100%%**********************]  1 of 1 completed
[2023-11-06T17:21:20.899+0000] {logging_mixin.py:151} INFO - [*********************100%%**********************]  1 of 1 completed
[2023-11-06T17:21:35.806+0000] {logging_mixin.py:151} INFO - [*********************100%%**********************]  1 of 1 completed
[2023-11-06T17:21:35.929+0000] {multi.py:178} ERROR - 
1 Failed download:
[2023-11-06T17:21:35.976+0000] {multi.py:191} ERROR - ['TSLA']: Exception('%ticker%: No price data found, symbol may be delisted (1d 2023-10-30 -> 2023-11-06)')
[2023-11-06T17:21:56.701+0000] {logging_mixin.py:151} INFO - [*********************100%%**********************]  1 of 1 completed
[2023-11-06T17:21:57.043+0000] {multi.py:178} ERROR - 
1 Failed download:
[2023-11-06T17:21:57.105+0000] {multi.py:191} ERROR - ['NVDA']: Exception('%ticker%: No price data found, symbol may be delisted (1d 2023-10-30 -> 2023-11-06)')
[2023-11-06T17:22:04.196+0000] {logging_mixin.py:151} INFO - [*********************100%%**********************]  1 of 1 completed
[2023-11-06T17:22:04.230+0000] {multi.py:178} ERROR - 
1 Failed download:
[2023-11-06T17:22:04.280+0000] {multi.py:191} ERROR - ['FB']: Exception('%ticker%: No timezone found, symbol may be delisted')
[2023-11-06T17:22:08.901+0000] {logging_mixin.py:151} INFO - [*********************100%%**********************]  1 of 1 completed
[2023-11-06T17:22:12.197+0000] {logging_mixin.py:151} INFO - [*********************100%%**********************]  1 of 1 completed
[2023-11-06T17:22:13.609+0000] {logging_mixin.py:151} INFO - [*********************100%%**********************]  1 of 1 completed
[2023-11-06T17:22:15.455+0000] {logging_mixin.py:151} INFO - [*********************100%%**********************]  1 of 1 completed
[2023-11-06T17:22:18.721+0000] {logging_mixin.py:151} INFO - [*********************100%%**********************]  1 of 1 completed
[2023-11-06T17:22:23.818+0000] {logging_mixin.py:151} INFO - [*********************100%%**********************]  1 of 1 completed
[2023-11-06T17:24:18.169+0000] {logging_mixin.py:151} INFO - [*********************100%%**********************]  1 of 1 completed
[2023-11-06T17:24:18.357+0000] {multi.py:178} ERROR - 
1 Failed download:
[2023-11-06T17:24:18.375+0000] {multi.py:191} ERROR - ['^RUT']: Exception('%ticker%: No price data found, symbol may be delisted (1d 2023-10-30 -> 2023-11-06)')
[2023-11-06T17:24:20.354+0000] {logging_mixin.py:151} INFO - Current Working Directory: /opt/***
[2023-11-06T17:24:20.656+0000] {taskinstance.py:1937} ERROR - Task failed with exception
Traceback (most recent call last):
  File "/home/airflow/.local/lib/python3.8/site-packages/airflow/operators/python.py", line 192, in execute
    return_value = self.execute_callable()
  File "/home/airflow/.local/lib/python3.8/site-packages/airflow/operators/python.py", line 209, in execute_callable
    return self.python_callable(*self.op_args, **self.op_kwargs)
  File "/opt/airflow/dags/yahoo_elt_pipeline.py", line 58, in extract_data
    stock_data_df.to_csv(stock_file_name, index=False)
  File "/home/airflow/.local/lib/python3.8/site-packages/pandas/core/generic.py", line 3772, in to_csv
    return DataFrameRenderer(formatter).to_csv(
  File "/home/airflow/.local/lib/python3.8/site-packages/pandas/io/formats/format.py", line 1186, in to_csv
    csv_formatter.save()
  File "/home/airflow/.local/lib/python3.8/site-packages/pandas/io/formats/csvs.py", line 240, in save
    with get_handle(
  File "/home/airflow/.local/lib/python3.8/site-packages/pandas/io/common.py", line 737, in get_handle
    check_parent_directory(str(handle))
  File "/home/airflow/.local/lib/python3.8/site-packages/pandas/io/common.py", line 600, in check_parent_directory
    raise OSError(rf"Cannot save file into a non-existent directory: '{parent}'")
OSError: Cannot save file into a non-existent directory: '../data/stock_data'
[2023-11-06T17:24:21.556+0000] {taskinstance.py:1400} INFO - Marking task as UP_FOR_RETRY. dag_id=yahoo_finance_elt_pipeline_v2, task_id=extract_data_task, execution_date=20231106T171419, start_date=20231106T172049, end_date=20231106T172421
[2023-11-06T17:24:23.702+0000] {standard_task_runner.py:104} ERROR - Failed to execute job 8 for task extract_data_task (Cannot save file into a non-existent directory: '../data/stock_data'; 1316)
[2023-11-06T17:24:24.372+0000] {local_task_job_runner.py:228} INFO - Task exited with return code 1
[2023-11-06T17:24:24.973+0000] {taskinstance.py:2784} INFO - Skipping mini scheduling run due to exception: None
Traceback (most recent call last):
  File "/home/airflow/.local/lib/python3.8/site-packages/sqlalchemy/engine/base.py", line 3371, in _wrap_pool_connect
    return fn()
  File "/home/airflow/.local/lib/python3.8/site-packages/sqlalchemy/pool/base.py", line 327, in connect
    return _ConnectionFairy._checkout(self)
  File "/home/airflow/.local/lib/python3.8/site-packages/sqlalchemy/pool/base.py", line 894, in _checkout
    fairy = _ConnectionRecord.checkout(pool)
  File "/home/airflow/.local/lib/python3.8/site-packages/sqlalchemy/pool/base.py", line 493, in checkout
    rec = pool._do_get()
  File "/home/airflow/.local/lib/python3.8/site-packages/sqlalchemy/pool/impl.py", line 256, in _do_get
    return self._create_connection()
  File "/home/airflow/.local/lib/python3.8/site-packages/sqlalchemy/pool/base.py", line 273, in _create_connection
    return _ConnectionRecord(self)
  File "/home/airflow/.local/lib/python3.8/site-packages/sqlalchemy/pool/base.py", line 388, in __init__
    self.__connect()
  File "/home/airflow/.local/lib/python3.8/site-packages/sqlalchemy/pool/base.py", line 691, in __connect
    pool.logger.debug("Error on connect(): %s", e)
  File "/home/airflow/.local/lib/python3.8/site-packages/sqlalchemy/util/langhelpers.py", line 70, in __exit__
    compat.raise_(
  File "/home/airflow/.local/lib/python3.8/site-packages/sqlalchemy/util/compat.py", line 211, in raise_
    raise exception
  File "/home/airflow/.local/lib/python3.8/site-packages/sqlalchemy/pool/base.py", line 686, in __connect
    self.dbapi_connection = connection = pool._invoke_creator(self)
  File "/home/airflow/.local/lib/python3.8/site-packages/sqlalchemy/engine/create.py", line 574, in connect
    return dialect.connect(*cargs, **cparams)
  File "/home/airflow/.local/lib/python3.8/site-packages/sqlalchemy/engine/default.py", line 598, in connect
    return self.dbapi.connect(*cargs, **cparams)
  File "/home/airflow/.local/lib/python3.8/site-packages/psycopg2/__init__.py", line 122, in connect
    conn = _connect(dsn, connection_factory=connection_factory, **kwasync)
psycopg2.OperationalError: could not translate host name "postgres" to address: Temporary failure in name resolution


The above exception was the direct cause of the following exception:

Traceback (most recent call last):
  File "/home/airflow/.local/lib/python3.8/site-packages/airflow/models/taskinstance.py", line 2733, in schedule_downstream_tasks
    dag_run = with_row_locks(
  File "/home/airflow/.local/lib/python3.8/site-packages/sqlalchemy/orm/query.py", line 2870, in one
    return self._iter().one()
  File "/home/airflow/.local/lib/python3.8/site-packages/sqlalchemy/orm/query.py", line 2916, in _iter
    result = self.session.execute(
  File "/home/airflow/.local/lib/python3.8/site-packages/sqlalchemy/orm/session.py", line 1716, in execute
    conn = self._connection_for_bind(bind)
  File "/home/airflow/.local/lib/python3.8/site-packages/sqlalchemy/orm/session.py", line 1555, in _connection_for_bind
    return self._transaction._connection_for_bind(
  File "/home/airflow/.local/lib/python3.8/site-packages/sqlalchemy/orm/session.py", line 750, in _connection_for_bind
    conn = bind.connect()
  File "/home/airflow/.local/lib/python3.8/site-packages/sqlalchemy/future/engine.py", line 406, in connect
    return super(Engine, self).connect()
  File "/home/airflow/.local/lib/python3.8/site-packages/sqlalchemy/engine/base.py", line 3325, in connect
    return self._connection_cls(self, close_with_result=close_with_result)
  File "/home/airflow/.local/lib/python3.8/site-packages/sqlalchemy/engine/base.py", line 96, in __init__
    else engine.raw_connection()
  File "/home/airflow/.local/lib/python3.8/site-packages/sqlalchemy/engine/base.py", line 3404, in raw_connection
    return self._wrap_pool_connect(self.pool.connect, _connection)
  File "/home/airflow/.local/lib/python3.8/site-packages/sqlalchemy/engine/base.py", line 3374, in _wrap_pool_connect
    Connection._handle_dbapi_exception_noconnection(
  File "/home/airflow/.local/lib/python3.8/site-packages/sqlalchemy/engine/base.py", line 2208, in _handle_dbapi_exception_noconnection
    util.raise_(
  File "/home/airflow/.local/lib/python3.8/site-packages/sqlalchemy/util/compat.py", line 211, in raise_
    raise exception
  File "/home/airflow/.local/lib/python3.8/site-packages/sqlalchemy/engine/base.py", line 3371, in _wrap_pool_connect
    return fn()
  File "/home/airflow/.local/lib/python3.8/site-packages/sqlalchemy/pool/base.py", line 327, in connect
    return _ConnectionFairy._checkout(self)
  File "/home/airflow/.local/lib/python3.8/site-packages/sqlalchemy/pool/base.py", line 894, in _checkout
    fairy = _ConnectionRecord.checkout(pool)
  File "/home/airflow/.local/lib/python3.8/site-packages/sqlalchemy/pool/base.py", line 493, in checkout
    rec = pool._do_get()
  File "/home/airflow/.local/lib/python3.8/site-packages/sqlalchemy/pool/impl.py", line 256, in _do_get
    return self._create_connection()
  File "/home/airflow/.local/lib/python3.8/site-packages/sqlalchemy/pool/base.py", line 273, in _create_connection
    return _ConnectionRecord(self)
  File "/home/airflow/.local/lib/python3.8/site-packages/sqlalchemy/pool/base.py", line 388, in __init__
    self.__connect()
  File "/home/airflow/.local/lib/python3.8/site-packages/sqlalchemy/pool/base.py", line 691, in __connect
    pool.logger.debug("Error on connect(): %s", e)
  File "/home/airflow/.local/lib/python3.8/site-packages/sqlalchemy/util/langhelpers.py", line 70, in __exit__
    compat.raise_(
  File "/home/airflow/.local/lib/python3.8/site-packages/sqlalchemy/util/compat.py", line 211, in raise_
    raise exception
  File "/home/airflow/.local/lib/python3.8/site-packages/sqlalchemy/pool/base.py", line 686, in __connect
    self.dbapi_connection = connection = pool._invoke_creator(self)
  File "/home/airflow/.local/lib/python3.8/site-packages/sqlalchemy/engine/create.py", line 574, in connect
    return dialect.connect(*cargs, **cparams)
  File "/home/airflow/.local/lib/python3.8/site-packages/sqlalchemy/engine/default.py", line 598, in connect
    return self.dbapi.connect(*cargs, **cparams)
  File "/home/airflow/.local/lib/python3.8/site-packages/psycopg2/__init__.py", line 122, in connect
    conn = _connect(dsn, connection_factory=connection_factory, **kwasync)
sqlalchemy.exc.OperationalError: (psycopg2.OperationalError) could not translate host name "postgres" to address: Temporary failure in name resolution

(Background on this error at: https://sqlalche.me/e/14/e3q8)
