[2023-11-07T01:28:35.821+0000] {taskinstance.py:1159} INFO - Dependencies all met for dep_context=non-requeueable deps ti=<TaskInstance: yahoo_finance_elt_pipeline_v13.load_to_s3_task manual__2023-11-07T01:27:40.445804+00:00 [queued]>
[2023-11-07T01:28:35.920+0000] {taskinstance.py:1159} INFO - Dependencies all met for dep_context=requeueable deps ti=<TaskInstance: yahoo_finance_elt_pipeline_v13.load_to_s3_task manual__2023-11-07T01:27:40.445804+00:00 [queued]>
[2023-11-07T01:28:35.926+0000] {taskinstance.py:1361} INFO - Starting attempt 1 of 6
[2023-11-07T01:28:36.059+0000] {taskinstance.py:1382} INFO - Executing <Task(PythonOperator): load_to_s3_task> on 2023-11-07 01:27:40.445804+00:00
[2023-11-07T01:28:36.097+0000] {standard_task_runner.py:57} INFO - Started process 921 to run task
[2023-11-07T01:28:36.144+0000] {standard_task_runner.py:84} INFO - Running: ['***', 'tasks', 'run', 'yahoo_finance_elt_pipeline_v13', 'load_to_s3_task', 'manual__2023-11-07T01:27:40.445804+00:00', '--job-id', '11', '--raw', '--subdir', 'DAGS_FOLDER/yahoo_elt_pipeline.py', '--cfg-path', '/tmp/tmpfb31hs16']
[2023-11-07T01:28:36.171+0000] {standard_task_runner.py:85} INFO - Job 11: Subtask load_to_s3_task
[2023-11-07T01:28:37.169+0000] {task_command.py:416} INFO - Running <TaskInstance: yahoo_finance_elt_pipeline_v13.load_to_s3_task manual__2023-11-07T01:27:40.445804+00:00 [running]> on host 57084f613782
[2023-11-07T01:28:38.228+0000] {taskinstance.py:1662} INFO - Exporting env vars: AIRFLOW_CTX_DAG_OWNER='mbahraoui' AIRFLOW_CTX_DAG_ID='yahoo_finance_elt_pipeline_v13' AIRFLOW_CTX_TASK_ID='load_to_s3_task' AIRFLOW_CTX_EXECUTION_DATE='2023-11-07T01:27:40.445804+00:00' AIRFLOW_CTX_TRY_NUMBER='1' AIRFLOW_CTX_DAG_RUN_ID='manual__2023-11-07T01:27:40.445804+00:00'
[2023-11-07T01:28:45.829+0000] {logging_mixin.py:151} INFO - None
[2023-11-07T01:28:45.880+0000] {logging_mixin.py:151} INFO - None
[2023-11-07T01:28:46.275+0000] {taskinstance.py:1937} ERROR - Task failed with exception
Traceback (most recent call last):
  File "/home/airflow/.local/lib/python3.8/site-packages/airflow/operators/python.py", line 192, in execute
    return_value = self.execute_callable()
  File "/home/airflow/.local/lib/python3.8/site-packages/airflow/operators/python.py", line 209, in execute_callable
    return self.python_callable(*self.op_args, **self.op_kwargs)
  File "/opt/airflow/dags/yahoo_elt_pipeline.py", line 77, in load_to_s3
    s3.upload_file(f"/tmp/stock_data_{end_date}.csv", s3_bucket_name, f"stock_data/stock_data_{end_date}.csv")
  File "/home/airflow/.local/lib/python3.8/site-packages/boto3/s3/inject.py", line 143, in upload_file
    return transfer.upload_file(
  File "/home/airflow/.local/lib/python3.8/site-packages/boto3/s3/transfer.py", line 292, in upload_file
    future.result()
  File "/home/airflow/.local/lib/python3.8/site-packages/s3transfer/futures.py", line 103, in result
    return self._coordinator.result()
  File "/home/airflow/.local/lib/python3.8/site-packages/s3transfer/futures.py", line 266, in result
    raise self._exception
  File "/home/airflow/.local/lib/python3.8/site-packages/s3transfer/tasks.py", line 139, in __call__
    return self._execute_main(kwargs)
  File "/home/airflow/.local/lib/python3.8/site-packages/s3transfer/tasks.py", line 162, in _execute_main
    return_value = self._main(**kwargs)
  File "/home/airflow/.local/lib/python3.8/site-packages/s3transfer/upload.py", line 758, in _main
    client.put_object(Bucket=bucket, Key=key, Body=body, **extra_args)
  File "/home/airflow/.local/lib/python3.8/site-packages/botocore/client.py", line 535, in _api_call
    return self._make_api_call(operation_name, kwargs)
  File "/home/airflow/.local/lib/python3.8/site-packages/botocore/client.py", line 963, in _make_api_call
    http, parsed_response = self._make_request(
  File "/home/airflow/.local/lib/python3.8/site-packages/botocore/client.py", line 986, in _make_request
    return self._endpoint.make_request(operation_model, request_dict)
  File "/home/airflow/.local/lib/python3.8/site-packages/botocore/endpoint.py", line 119, in make_request
    return self._send_request(request_dict, operation_model)
  File "/home/airflow/.local/lib/python3.8/site-packages/botocore/endpoint.py", line 198, in _send_request
    request = self.create_request(request_dict, operation_model)
  File "/home/airflow/.local/lib/python3.8/site-packages/botocore/endpoint.py", line 134, in create_request
    self._event_emitter.emit(
  File "/home/airflow/.local/lib/python3.8/site-packages/botocore/hooks.py", line 412, in emit
    return self._emitter.emit(aliased_event_name, **kwargs)
  File "/home/airflow/.local/lib/python3.8/site-packages/botocore/hooks.py", line 256, in emit
    return self._emit(event_name, kwargs)
  File "/home/airflow/.local/lib/python3.8/site-packages/botocore/hooks.py", line 239, in _emit
    response = handler(**kwargs)
  File "/home/airflow/.local/lib/python3.8/site-packages/botocore/signers.py", line 105, in handler
    return self.sign(operation_name, request)
  File "/home/airflow/.local/lib/python3.8/site-packages/botocore/signers.py", line 189, in sign
    auth.add_auth(request)
  File "/home/airflow/.local/lib/python3.8/site-packages/botocore/auth.py", line 418, in add_auth
    raise NoCredentialsError()
botocore.exceptions.NoCredentialsError: Unable to locate credentials
[2023-11-07T01:28:46.847+0000] {taskinstance.py:1400} INFO - Marking task as UP_FOR_RETRY. dag_id=yahoo_finance_elt_pipeline_v13, task_id=load_to_s3_task, execution_date=20231107T012740, start_date=20231107T012835, end_date=20231107T012846
[2023-11-07T01:28:47.014+0000] {standard_task_runner.py:104} ERROR - Failed to execute job 11 for task load_to_s3_task (Unable to locate credentials; 921)
[2023-11-07T01:28:47.274+0000] {local_task_job_runner.py:228} INFO - Task exited with return code 1
[2023-11-07T01:28:47.528+0000] {taskinstance.py:2778} INFO - 0 downstream tasks scheduled from follow-on schedule check
