[2023-11-07T00:16:38.533+0000] {taskinstance.py:1159} INFO - Dependencies all met for dep_context=non-requeueable deps ti=<TaskInstance: yahoo_finance_elt_pipeline_v4.load_to_s3_task manual__2023-11-07T00:09:48.674000+00:00 [queued]>
[2023-11-07T00:16:38.576+0000] {taskinstance.py:1159} INFO - Dependencies all met for dep_context=requeueable deps ti=<TaskInstance: yahoo_finance_elt_pipeline_v4.load_to_s3_task manual__2023-11-07T00:09:48.674000+00:00 [queued]>
[2023-11-07T00:16:38.579+0000] {taskinstance.py:1361} INFO - Starting attempt 2 of 6
[2023-11-07T00:16:38.650+0000] {taskinstance.py:1382} INFO - Executing <Task(PythonOperator): load_to_s3_task> on 2023-11-07 00:09:48.674000+00:00
[2023-11-07T00:16:38.672+0000] {standard_task_runner.py:57} INFO - Started process 954 to run task
[2023-11-07T00:16:38.698+0000] {standard_task_runner.py:84} INFO - Running: ['***', 'tasks', 'run', 'yahoo_finance_elt_pipeline_v4', 'load_to_s3_task', 'manual__2023-11-07T00:09:48.674000+00:00', '--job-id', '48', '--raw', '--subdir', 'DAGS_FOLDER/yahoo_elt_pipeline.py', '--cfg-path', '/tmp/tmpd8bol9ax']
[2023-11-07T00:16:38.708+0000] {standard_task_runner.py:85} INFO - Job 48: Subtask load_to_s3_task
[2023-11-07T00:16:38.950+0000] {task_command.py:416} INFO - Running <TaskInstance: yahoo_finance_elt_pipeline_v4.load_to_s3_task manual__2023-11-07T00:09:48.674000+00:00 [running]> on host a5d58a06784e
[2023-11-07T00:16:39.547+0000] {taskinstance.py:1662} INFO - Exporting env vars: AIRFLOW_CTX_DAG_OWNER='mbahraoui' AIRFLOW_CTX_DAG_ID='yahoo_finance_elt_pipeline_v4' AIRFLOW_CTX_TASK_ID='load_to_s3_task' AIRFLOW_CTX_EXECUTION_DATE='2023-11-07T00:09:48.674000+00:00' AIRFLOW_CTX_TRY_NUMBER='2' AIRFLOW_CTX_DAG_RUN_ID='manual__2023-11-07T00:09:48.674000+00:00'
[2023-11-07T00:16:42.102+0000] {taskinstance.py:1937} ERROR - Task failed with exception
Traceback (most recent call last):
  File "/home/airflow/.local/lib/python3.8/site-packages/airflow/operators/python.py", line 192, in execute
    return_value = self.execute_callable()
  File "/home/airflow/.local/lib/python3.8/site-packages/airflow/operators/python.py", line 209, in execute_callable
    return self.python_callable(*self.op_args, **self.op_kwargs)
  File "/opt/airflow/dags/yahoo_elt_pipeline.py", line 58, in load_to_s3
    company_object = s3.Object(s3_bucket_name, 'company_info.csv')
  File "/home/airflow/.local/lib/python3.8/site-packages/botocore/client.py", line 888, in __getattr__
    raise AttributeError(
AttributeError: 'S3' object has no attribute 'Object'
[2023-11-07T00:16:42.143+0000] {taskinstance.py:1400} INFO - Marking task as UP_FOR_RETRY. dag_id=yahoo_finance_elt_pipeline_v4, task_id=load_to_s3_task, execution_date=20231107T000948, start_date=20231107T001638, end_date=20231107T001642
[2023-11-07T00:16:42.212+0000] {standard_task_runner.py:104} ERROR - Failed to execute job 48 for task load_to_s3_task ('S3' object has no attribute 'Object'; 954)
[2023-11-07T00:16:42.303+0000] {local_task_job_runner.py:228} INFO - Task exited with return code 1
[2023-11-07T00:16:42.358+0000] {taskinstance.py:2778} INFO - 0 downstream tasks scheduled from follow-on schedule check
