[2023-11-06T16:55:47.000+0000] {taskinstance.py:1159} INFO - Dependencies all met for dep_context=non-requeueable deps ti=<TaskInstance: yahoo_finance_elt_pipeline_v01.extract_data_task manual__2023-11-06T16:55:27.673604+00:00 [queued]>
[2023-11-06T16:55:47.372+0000] {taskinstance.py:1159} INFO - Dependencies all met for dep_context=requeueable deps ti=<TaskInstance: yahoo_finance_elt_pipeline_v01.extract_data_task manual__2023-11-06T16:55:27.673604+00:00 [queued]>
[2023-11-06T16:55:47.456+0000] {taskinstance.py:1361} INFO - Starting attempt 1 of 6
[2023-11-06T16:55:47.990+0000] {taskinstance.py:1382} INFO - Executing <Task(PythonOperator): extract_data_task> on 2023-11-06 16:55:27.673604+00:00
[2023-11-06T16:55:48.117+0000] {standard_task_runner.py:57} INFO - Started process 659 to run task
[2023-11-06T16:55:48.359+0000] {standard_task_runner.py:84} INFO - Running: ['***', 'tasks', 'run', 'yahoo_finance_elt_pipeline_v01', 'extract_data_task', 'manual__2023-11-06T16:55:27.673604+00:00', '--job-id', '3', '--raw', '--subdir', 'DAGS_FOLDER/yahoo_elt_pipeline.py', '--cfg-path', '/tmp/tmpmi1spfcg']
[2023-11-06T16:55:48.461+0000] {standard_task_runner.py:85} INFO - Job 3: Subtask extract_data_task
[2023-11-06T16:55:49.589+0000] {task_command.py:416} INFO - Running <TaskInstance: yahoo_finance_elt_pipeline_v01.extract_data_task manual__2023-11-06T16:55:27.673604+00:00 [running]> on host a5d58a06784e
[2023-11-06T16:55:51.211+0000] {taskinstance.py:1662} INFO - Exporting env vars: AIRFLOW_CTX_DAG_OWNER='mbahraoui' AIRFLOW_CTX_DAG_ID='yahoo_finance_elt_pipeline_v01' AIRFLOW_CTX_TASK_ID='extract_data_task' AIRFLOW_CTX_EXECUTION_DATE='2023-11-06T16:55:27.673604+00:00' AIRFLOW_CTX_TRY_NUMBER='1' AIRFLOW_CTX_DAG_RUN_ID='manual__2023-11-06T16:55:27.673604+00:00'
[2023-11-06T16:55:51.243+0000] {taskinstance.py:1937} ERROR - Task failed with exception
Traceback (most recent call last):
  File "/home/airflow/.local/lib/python3.8/site-packages/airflow/operators/python.py", line 192, in execute
    return_value = self.execute_callable()
  File "/home/airflow/.local/lib/python3.8/site-packages/airflow/operators/python.py", line 209, in execute_callable
    return self.python_callable(*self.op_args, **self.op_kwargs)
  File "/opt/airflow/dags/yahoo_elt_pipeline.py", line 27, in extract_data
    end_date = datetime.datetime.today().date()
AttributeError: type object 'datetime.datetime' has no attribute 'datetime'
[2023-11-06T16:55:51.367+0000] {taskinstance.py:1400} INFO - Marking task as UP_FOR_RETRY. dag_id=yahoo_finance_elt_pipeline_v01, task_id=extract_data_task, execution_date=20231106T165527, start_date=20231106T165547, end_date=20231106T165551
[2023-11-06T16:55:51.553+0000] {standard_task_runner.py:104} ERROR - Failed to execute job 3 for task extract_data_task (type object 'datetime.datetime' has no attribute 'datetime'; 659)
[2023-11-06T16:55:51.719+0000] {local_task_job_runner.py:228} INFO - Task exited with return code 1
[2023-11-06T16:55:51.901+0000] {taskinstance.py:2778} INFO - 0 downstream tasks scheduled from follow-on schedule check
