[2023-11-07T00:24:56.136+0000] {taskinstance.py:1159} INFO - Dependencies all met for dep_context=non-requeueable deps ti=<TaskInstance: yahoo_finance_elt_pipeline_v5.load_to_s3_task manual__2023-11-07T00:23:52.542145+00:00 [queued]>
[2023-11-07T00:24:56.198+0000] {taskinstance.py:1159} INFO - Dependencies all met for dep_context=requeueable deps ti=<TaskInstance: yahoo_finance_elt_pipeline_v5.load_to_s3_task manual__2023-11-07T00:23:52.542145+00:00 [queued]>
[2023-11-07T00:24:56.200+0000] {taskinstance.py:1361} INFO - Starting attempt 1 of 6
[2023-11-07T00:24:56.283+0000] {taskinstance.py:1382} INFO - Executing <Task(PythonOperator): load_to_s3_task> on 2023-11-07 00:23:52.542145+00:00
[2023-11-07T00:24:56.335+0000] {standard_task_runner.py:57} INFO - Started process 1191 to run task
[2023-11-07T00:24:56.381+0000] {standard_task_runner.py:84} INFO - Running: ['***', 'tasks', 'run', 'yahoo_finance_elt_pipeline_v5', 'load_to_s3_task', 'manual__2023-11-07T00:23:52.542145+00:00', '--job-id', '51', '--raw', '--subdir', 'DAGS_FOLDER/yahoo_elt_pipeline.py', '--cfg-path', '/tmp/tmp7m77d4_n']
[2023-11-07T00:24:56.397+0000] {standard_task_runner.py:85} INFO - Job 51: Subtask load_to_s3_task
[2023-11-07T00:24:56.798+0000] {task_command.py:416} INFO - Running <TaskInstance: yahoo_finance_elt_pipeline_v5.load_to_s3_task manual__2023-11-07T00:23:52.542145+00:00 [running]> on host a5d58a06784e
[2023-11-07T00:24:57.358+0000] {taskinstance.py:1662} INFO - Exporting env vars: AIRFLOW_CTX_DAG_OWNER='mbahraoui' AIRFLOW_CTX_DAG_ID='yahoo_finance_elt_pipeline_v5' AIRFLOW_CTX_TASK_ID='load_to_s3_task' AIRFLOW_CTX_EXECUTION_DATE='2023-11-07T00:23:52.542145+00:00' AIRFLOW_CTX_TRY_NUMBER='1' AIRFLOW_CTX_DAG_RUN_ID='manual__2023-11-07T00:23:52.542145+00:00'
[2023-11-07T00:25:03.755+0000] {taskinstance.py:1937} ERROR - Task failed with exception
Traceback (most recent call last):
  File "/opt/airflow/dags/yahoo_elt_pipeline.py", line 19, in check_s3_object_existence
    s3.head_object(Bucket=bucket_name, Key=object_key)
NameError: name 's3' is not defined

During handling of the above exception, another exception occurred:

Traceback (most recent call last):
  File "/home/airflow/.local/lib/python3.8/site-packages/airflow/operators/python.py", line 192, in execute
    return_value = self.execute_callable()
  File "/home/airflow/.local/lib/python3.8/site-packages/airflow/operators/python.py", line 209, in execute_callable
    return self.python_callable(*self.op_args, **self.op_kwargs)
  File "/opt/airflow/dags/yahoo_elt_pipeline.py", line 69, in load_to_s3
    object_exists = check_s3_object_existence(s3_bucket_name, 'company_info.csv')
  File "/opt/airflow/dags/yahoo_elt_pipeline.py", line 22, in check_s3_object_existence
    if e.response['Error']['Code'] == '404':
AttributeError: 'NameError' object has no attribute 'response'
[2023-11-07T00:25:03.924+0000] {taskinstance.py:1400} INFO - Marking task as UP_FOR_RETRY. dag_id=yahoo_finance_elt_pipeline_v5, task_id=load_to_s3_task, execution_date=20231107T002352, start_date=20231107T002456, end_date=20231107T002503
[2023-11-07T00:25:04.162+0000] {standard_task_runner.py:104} ERROR - Failed to execute job 51 for task load_to_s3_task ('NameError' object has no attribute 'response'; 1191)
[2023-11-07T00:25:04.296+0000] {local_task_job_runner.py:228} INFO - Task exited with return code 1
[2023-11-07T00:25:04.371+0000] {taskinstance.py:2778} INFO - 0 downstream tasks scheduled from follow-on schedule check
