[2023-11-07T01:33:11.516+0000] {taskinstance.py:1159} INFO - Dependencies all met for dep_context=non-requeueable deps ti=<TaskInstance: yahoo_finance_elt_pipeline_v14.load_to_s3_task manual__2023-11-07T01:32:09.146118+00:00 [queued]>
[2023-11-07T01:33:11.585+0000] {taskinstance.py:1159} INFO - Dependencies all met for dep_context=requeueable deps ti=<TaskInstance: yahoo_finance_elt_pipeline_v14.load_to_s3_task manual__2023-11-07T01:32:09.146118+00:00 [queued]>
[2023-11-07T01:33:11.588+0000] {taskinstance.py:1361} INFO - Starting attempt 1 of 6
[2023-11-07T01:33:11.711+0000] {taskinstance.py:1382} INFO - Executing <Task(PythonOperator): load_to_s3_task> on 2023-11-07 01:32:09.146118+00:00
[2023-11-07T01:33:11.759+0000] {standard_task_runner.py:57} INFO - Started process 1056 to run task
[2023-11-07T01:33:11.804+0000] {standard_task_runner.py:84} INFO - Running: ['***', 'tasks', 'run', 'yahoo_finance_elt_pipeline_v14', 'load_to_s3_task', 'manual__2023-11-07T01:32:09.146118+00:00', '--job-id', '13', '--raw', '--subdir', 'DAGS_FOLDER/yahoo_elt_pipeline.py', '--cfg-path', '/tmp/tmprek8idk2']
[2023-11-07T01:33:11.849+0000] {standard_task_runner.py:85} INFO - Job 13: Subtask load_to_s3_task
[2023-11-07T01:33:12.207+0000] {task_command.py:416} INFO - Running <TaskInstance: yahoo_finance_elt_pipeline_v14.load_to_s3_task manual__2023-11-07T01:32:09.146118+00:00 [running]> on host 57084f613782
[2023-11-07T01:33:12.708+0000] {taskinstance.py:1662} INFO - Exporting env vars: AIRFLOW_CTX_DAG_OWNER='mbahraoui' AIRFLOW_CTX_DAG_ID='yahoo_finance_elt_pipeline_v14' AIRFLOW_CTX_TASK_ID='load_to_s3_task' AIRFLOW_CTX_EXECUTION_DATE='2023-11-07T01:32:09.146118+00:00' AIRFLOW_CTX_TRY_NUMBER='1' AIRFLOW_CTX_DAG_RUN_ID='manual__2023-11-07T01:32:09.146118+00:00'
[2023-11-07T01:33:12.721+0000] {taskinstance.py:1937} ERROR - Task failed with exception
Traceback (most recent call last):
  File "/home/airflow/.local/lib/python3.8/site-packages/airflow/operators/python.py", line 192, in execute
    return_value = self.execute_callable()
  File "/home/airflow/.local/lib/python3.8/site-packages/airflow/operators/python.py", line 209, in execute_callable
    return self.python_callable(*self.op_args, **self.op_kwargs)
  File "/opt/airflow/dags/yahoo_elt_pipeline.py", line 60, in load_to_s3
    aws_access_key_id = os.environ['ACCESS_KEY']
  File "/usr/local/lib/python3.8/os.py", line 675, in __getitem__
    raise KeyError(key) from None
KeyError: 'ACCESS_KEY'
[2023-11-07T01:33:12.800+0000] {taskinstance.py:1400} INFO - Marking task as UP_FOR_RETRY. dag_id=yahoo_finance_elt_pipeline_v14, task_id=load_to_s3_task, execution_date=20231107T013209, start_date=20231107T013311, end_date=20231107T013312
[2023-11-07T01:33:12.875+0000] {standard_task_runner.py:104} ERROR - Failed to execute job 13 for task load_to_s3_task ('ACCESS_KEY'; 1056)
[2023-11-07T01:33:12.979+0000] {local_task_job_runner.py:228} INFO - Task exited with return code 1
[2023-11-07T01:33:13.133+0000] {taskinstance.py:2778} INFO - 0 downstream tasks scheduled from follow-on schedule check
