[2023-11-06T17:00:45.029+0000] {taskinstance.py:1159} INFO - Dependencies all met for dep_context=non-requeueable deps ti=<TaskInstance: yahoo_finance_elt_pipeline_v02.extract_data_task manual__2023-11-06T17:00:31.478187+00:00 [queued]>
[2023-11-06T17:00:45.192+0000] {taskinstance.py:1159} INFO - Dependencies all met for dep_context=requeueable deps ti=<TaskInstance: yahoo_finance_elt_pipeline_v02.extract_data_task manual__2023-11-06T17:00:31.478187+00:00 [queued]>
[2023-11-06T17:00:45.209+0000] {taskinstance.py:1361} INFO - Starting attempt 1 of 6
[2023-11-06T17:00:45.393+0000] {taskinstance.py:1382} INFO - Executing <Task(PythonOperator): extract_data_task> on 2023-11-06 17:00:31.478187+00:00
[2023-11-06T17:00:45.436+0000] {standard_task_runner.py:57} INFO - Started process 786 to run task
[2023-11-06T17:00:45.493+0000] {standard_task_runner.py:84} INFO - Running: ['***', 'tasks', 'run', 'yahoo_finance_elt_pipeline_v02', 'extract_data_task', 'manual__2023-11-06T17:00:31.478187+00:00', '--job-id', '4', '--raw', '--subdir', 'DAGS_FOLDER/yahoo_elt_pipeline.py', '--cfg-path', '/tmp/tmpdcyk6rgt']
[2023-11-06T17:00:45.539+0000] {standard_task_runner.py:85} INFO - Job 4: Subtask extract_data_task
[2023-11-06T17:00:46.613+0000] {task_command.py:416} INFO - Running <TaskInstance: yahoo_finance_elt_pipeline_v02.extract_data_task manual__2023-11-06T17:00:31.478187+00:00 [running]> on host a5d58a06784e
[2023-11-06T17:00:47.761+0000] {taskinstance.py:1662} INFO - Exporting env vars: AIRFLOW_CTX_DAG_OWNER='mbahraoui' AIRFLOW_CTX_DAG_ID='yahoo_finance_elt_pipeline_v02' AIRFLOW_CTX_TASK_ID='extract_data_task' AIRFLOW_CTX_EXECUTION_DATE='2023-11-06T17:00:31.478187+00:00' AIRFLOW_CTX_TRY_NUMBER='1' AIRFLOW_CTX_DAG_RUN_ID='manual__2023-11-06T17:00:31.478187+00:00'
[2023-11-06T17:00:47.779+0000] {taskinstance.py:1937} ERROR - Task failed with exception
Traceback (most recent call last):
  File "/home/airflow/.local/lib/python3.8/site-packages/airflow/operators/python.py", line 192, in execute
    return_value = self.execute_callable()
  File "/home/airflow/.local/lib/python3.8/site-packages/airflow/operators/python.py", line 209, in execute_callable
    return self.python_callable(*self.op_args, **self.op_kwargs)
  File "/opt/airflow/dags/yahoo_elt_pipeline.py", line 29, in extract_data
    start_date = end_date - datetime.timedelta(days=days_back)
AttributeError: type object 'datetime.datetime' has no attribute 'timedelta'
[2023-11-06T17:00:47.850+0000] {taskinstance.py:1400} INFO - Marking task as UP_FOR_RETRY. dag_id=yahoo_finance_elt_pipeline_v02, task_id=extract_data_task, execution_date=20231106T170031, start_date=20231106T170045, end_date=20231106T170047
[2023-11-06T17:00:47.943+0000] {standard_task_runner.py:104} ERROR - Failed to execute job 4 for task extract_data_task (type object 'datetime.datetime' has no attribute 'timedelta'; 786)
[2023-11-06T17:00:48.067+0000] {local_task_job_runner.py:228} INFO - Task exited with return code 1
[2023-11-06T17:00:48.691+0000] {taskinstance.py:2778} INFO - 0 downstream tasks scheduled from follow-on schedule check
