[2023-11-07T01:09:14.545+0000] {taskinstance.py:1159} INFO - Dependencies all met for dep_context=non-requeueable deps ti=<TaskInstance: yahoo_finance_elt_pipeline_v11.load_to_s3_task manual__2023-11-07T01:05:40.482147+00:00 [queued]>
[2023-11-07T01:09:14.567+0000] {taskinstance.py:1159} INFO - Dependencies all met for dep_context=requeueable deps ti=<TaskInstance: yahoo_finance_elt_pipeline_v11.load_to_s3_task manual__2023-11-07T01:05:40.482147+00:00 [queued]>
[2023-11-07T01:09:14.568+0000] {taskinstance.py:1361} INFO - Starting attempt 1 of 6
[2023-11-07T01:09:14.595+0000] {taskinstance.py:1382} INFO - Executing <Task(PythonOperator): load_to_s3_task> on 2023-11-07 01:05:40.482147+00:00
[2023-11-07T01:09:14.606+0000] {standard_task_runner.py:57} INFO - Started process 398 to run task
[2023-11-07T01:09:14.614+0000] {standard_task_runner.py:84} INFO - Running: ['***', 'tasks', 'run', 'yahoo_finance_elt_pipeline_v11', 'load_to_s3_task', 'manual__2023-11-07T01:05:40.482147+00:00', '--job-id', '5', '--raw', '--subdir', 'DAGS_FOLDER/yahoo_elt_pipeline.py', '--cfg-path', '/tmp/tmpecztz7hv']
[2023-11-07T01:09:14.619+0000] {standard_task_runner.py:85} INFO - Job 5: Subtask load_to_s3_task
[2023-11-07T01:09:14.720+0000] {task_command.py:416} INFO - Running <TaskInstance: yahoo_finance_elt_pipeline_v11.load_to_s3_task manual__2023-11-07T01:05:40.482147+00:00 [running]> on host 57084f613782
[2023-11-07T01:09:14.895+0000] {taskinstance.py:1662} INFO - Exporting env vars: AIRFLOW_CTX_DAG_OWNER='mbahraoui' AIRFLOW_CTX_DAG_ID='yahoo_finance_elt_pipeline_v11' AIRFLOW_CTX_TASK_ID='load_to_s3_task' AIRFLOW_CTX_EXECUTION_DATE='2023-11-07T01:05:40.482147+00:00' AIRFLOW_CTX_TRY_NUMBER='1' AIRFLOW_CTX_DAG_RUN_ID='manual__2023-11-07T01:05:40.482147+00:00'
[2023-11-07T01:09:19.136+0000] {taskinstance.py:1937} ERROR - Task failed with exception
Traceback (most recent call last):
  File "/home/airflow/.local/lib/python3.8/site-packages/airflow/operators/python.py", line 192, in execute
    return_value = self.execute_callable()
  File "/home/airflow/.local/lib/python3.8/site-packages/airflow/operators/python.py", line 209, in execute_callable
    return self.python_callable(*self.op_args, **self.op_kwargs)
  File "/opt/airflow/dags/yahoo_elt_pipeline.py", line 69, in load_to_s3
    s3.upload_file('./company_info.csv', s3_bucket_name, 'company_info.csv')
  File "/home/airflow/.local/lib/python3.8/site-packages/boto3/s3/inject.py", line 143, in upload_file
    return transfer.upload_file(
  File "/home/airflow/.local/lib/python3.8/site-packages/boto3/s3/transfer.py", line 292, in upload_file
    future.result()
  File "/home/airflow/.local/lib/python3.8/site-packages/s3transfer/futures.py", line 103, in result
    return self._coordinator.result()
  File "/home/airflow/.local/lib/python3.8/site-packages/s3transfer/futures.py", line 266, in result
    raise self._exception
  File "/home/airflow/.local/lib/python3.8/site-packages/s3transfer/tasks.py", line 269, in _main
    self._submit(transfer_future=transfer_future, **kwargs)
  File "/home/airflow/.local/lib/python3.8/site-packages/s3transfer/upload.py", line 585, in _submit
    upload_input_manager.provide_transfer_size(transfer_future)
  File "/home/airflow/.local/lib/python3.8/site-packages/s3transfer/upload.py", line 244, in provide_transfer_size
    self._osutil.get_file_size(transfer_future.meta.call_args.fileobj)
  File "/home/airflow/.local/lib/python3.8/site-packages/s3transfer/utils.py", line 247, in get_file_size
    return os.path.getsize(filename)
  File "/usr/local/lib/python3.8/genericpath.py", line 50, in getsize
    return os.stat(filename).st_size
FileNotFoundError: [Errno 2] No such file or directory: './company_info.csv'
[2023-11-07T01:09:19.160+0000] {taskinstance.py:1400} INFO - Marking task as UP_FOR_RETRY. dag_id=yahoo_finance_elt_pipeline_v11, task_id=load_to_s3_task, execution_date=20231107T010540, start_date=20231107T010914, end_date=20231107T010919
[2023-11-07T01:09:19.186+0000] {standard_task_runner.py:104} ERROR - Failed to execute job 5 for task load_to_s3_task ([Errno 2] No such file or directory: './company_info.csv'; 398)
[2023-11-07T01:09:19.245+0000] {local_task_job_runner.py:228} INFO - Task exited with return code 1
[2023-11-07T01:09:19.311+0000] {taskinstance.py:2778} INFO - 0 downstream tasks scheduled from follow-on schedule check
